Traceback (most recent call last):
  File "/home/phuijse/.conda/envs/info183/lib/python3.8/site-packages/jupyter_cache/executors/utils.py", line 51, in single_nb_execution
    executenb(
  File "/home/phuijse/.conda/envs/info183/lib/python3.8/site-packages/nbclient/client.py", line 1082, in execute
    return NotebookClient(nb=nb, resources=resources, km=km, **kwargs).execute()
  File "/home/phuijse/.conda/envs/info183/lib/python3.8/site-packages/nbclient/util.py", line 74, in wrapped
    return just_run(coro(*args, **kwargs))
  File "/home/phuijse/.conda/envs/info183/lib/python3.8/site-packages/nbclient/util.py", line 53, in just_run
    return loop.run_until_complete(coro)
  File "/home/phuijse/.conda/envs/info183/lib/python3.8/asyncio/base_events.py", line 616, in run_until_complete
    return future.result()
  File "/home/phuijse/.conda/envs/info183/lib/python3.8/site-packages/nbclient/client.py", line 535, in async_execute
    await self.async_execute_cell(
  File "/home/phuijse/.conda/envs/info183/lib/python3.8/site-packages/nbclient/client.py", line 827, in async_execute_cell
    self._check_raise_for_error(cell, exec_reply)
  File "/home/phuijse/.conda/envs/info183/lib/python3.8/site-packages/nbclient/client.py", line 735, in _check_raise_for_error
    raise CellExecutionError.from_cell_and_msg(cell, exec_reply['content'])
nbclient.exceptions.CellExecutionError: An error occurred while executing the following cell:
------------------
plt.close('all'); fig, ax = plt.subplots(1, 2, figsize=(6, 3))
t = np.linspace(-5, 5, num=500); f = np.linspace(-5, 5, num=500)
ax[0].set_xlabel('Time [s]'); ax[1].set_xlabel('Frequency [Hz]');
line_square = ax[0].plot(t, np.zeros_like(t), linewidth=4); ax[0].set_ylim([-.1, 1.1])
line_gabor1 = ax[0].plot([-1, 1], [0, 0], 'r--')
line_sinc = ax[1].plot(f, np.zeros_like(f), linewidth=4)
line_gabor2 = ax[1].plot([-0.5, 0.5], [0, 0], 'r--')

def update(T):    
    s = np.zeros_like(t); s[(t> - T) & (t<  T)] = 1    
    line_square[0].set_ydata(s);  line_gabor1[0].set_xdata([-T, T])
    S = 2*T*np.sinc(2*f*T); line_sinc[0].set_ydata(S); 
    line_gabor2[0].set_xdata([-0.5/T, 0.5/T])
    ax[1].set_ylim([-2*T/np.pi, 2.2*T])
    
interact(update, T=SelectionSlider_nice(options=[1/8, 1/4, 1/2, 1, 2, 4], value=1));
------------------

[0;31m---------------------------------------------------------------------------[0m
[0;31mNameError[0m                                 Traceback (most recent call last)
[0;32m<ipython-input-2-bd97bb0459ec>[0m in [0;36m<module>[0;34m[0m
[1;32m     14[0m     [0max[0m[0;34m[[0m[0;36m1[0m[0;34m][0m[0;34m.[0m[0mset_ylim[0m[0;34m([0m[0;34m[[0m[0;34m-[0m[0;36m2[0m[0;34m*[0m[0mT[0m[0;34m/[0m[0mnp[0m[0;34m.[0m[0mpi[0m[0;34m,[0m [0;36m2.2[0m[0;34m*[0m[0mT[0m[0;34m][0m[0;34m)[0m[0;34m[0m[0;34m[0m[0m
[1;32m     15[0m [0;34m[0m[0m
[0;32m---> 16[0;31m [0minteract[0m[0;34m([0m[0mupdate[0m[0;34m,[0m [0mT[0m[0;34m=[0m[0mSelectionSlider_nice[0m[0;34m([0m[0moptions[0m[0;34m=[0m[0;34m[[0m[0;36m1[0m[0;34m/[0m[0;36m8[0m[0;34m,[0m [0;36m1[0m[0;34m/[0m[0;36m4[0m[0;34m,[0m [0;36m1[0m[0;34m/[0m[0;36m2[0m[0;34m,[0m [0;36m1[0m[0;34m,[0m [0;36m2[0m[0;34m,[0m [0;36m4[0m[0;34m][0m[0;34m,[0m [0mvalue[0m[0;34m=[0m[0;36m1[0m[0;34m)[0m[0;34m)[0m[0;34m;[0m[0;34m[0m[0;34m[0m[0m
[0m
[0;31mNameError[0m: name 'interact' is not defined
NameError: name 'interact' is not defined

